package chap14_exception;

public class _02_generateException {

	public static void main(String[] args) {
		// TODO Auto-generated method stub
		try {
//			ArrayIndexOutOfBoundsException aie = 
//					new ArrayIndexOutOfBoundsException("인덱스가 초과됐습니다.");
//			throw aie;
			
			//1. NullPointerException
			
			//2. ArithmeticException
			
			NullPointerException npe = new NullPointerException("Null 값이 포함되어 있습니다.");
			throw npe;
			
//			ArithmeticException aee = new ArithmeticException("수학적 오류가 생겼습니다.");
//			throw aee;
			
		}catch(NullPointerException ne) {
			
		}catch(ArithmeticException ae) {
			System.out.println(ae.getMessage());
		}catch(Exception e) {
		//마지막 catch문은 위에 선언한 catch문을 다 통과한 예외들을 처리할 수 있게
		//모든 예외를 담을 수 있는 예외의 최상위 클래스 Exception으로 예외를 처리해준다.
			System.out.println(e.getMessage());
		}
	}

}
